from mine import *
import time
mc=Minecraft()
position=mc.player.getTilePos()

x=position.x
y=position.y
z=position.z
blockType=49

mc.setBlocks(x,y-1,z,x+2,y-1,z+1,5)
mc.setBlocks(x+4,y-3,z,x+5,y-3,z+1,29,1)
mc.setBlocks(x+4,y-2,z,x+5,y-2,z+1,165)
mc.setBlock(x+4,y-3,z-1,blockType)
mc.setBlock(x+4,y-3,z-2,76,4)
mc.setBlock(x+4,y-2,z-2,159)
mc.setBlocks(x+6,y-3,z+3,x+6,y-3,z+1,159)
mc.setBlocks(x+6,y-2,z+3,x+6,y-2,z+2,55)
mc.setBlocks(x+6,y-2,z+4,x+5,y-2,z+4,159)
mc.setBlocks(x+6,y-1,z+4,x+5,y-1,z+4,55)
mc.setBlock(x+5,y-1,z+5,55)
mc.setBlock(x+5,y-2,z+5,159)
mc.setBlock(x+4,y-1,z-2,55)
mc.setBlock(x+5,y-3,z-1,93,7)
mc.setBlock(x+6,y-3,z-1,159)
mc.setBlock(x+6,y-2,z-1,55)
mc.setBlock(x+6,y-2,z+1,93,12)
mc.setBlock(x+6,y-2,z,blockType)
mc.setBlock(x+6,y-2,z+1,93,12)
mc.setBlocks(x+4,y-1,z,x+5,y-1,z+1,17)
mc.setBlock(x+5,y-1,z-2,159)
mc.setBlock(x+5,y,z-2,55)
mc.setBlock(x+6,y-1,z-2,159)
mc.setBlock(x+6,y,z-2,93,5)
mc.setBlock(x+3,y-1,z,blockType)
mc.setBlock(x+3,y-1,z+1,blockType)
mc.setBlock(x+3,y-1,z,blockType)
mc.setBlock(x+6,y-1,z+2,blockType)
mc.setBlock(x+6,y-1,z+3,89)
mc.setBlock(x+6,y,z+3,55)
mc.setBlock(x+6,y,z+2,93,8)
mc.setBlocks(x+4,y-1,z+4,x+3,y-1,z+5,159)
mc.setBlocks(x+4,y,z+4,x+3,y,z+5,55)
mc.setBlock(x+4,y,z+5,93,11)
mc.setBlocks(x+4,y,z-1,x+5,y,z-1,blockType)
mc.setBlocks(x+6,y,z,x+6,y,z+1,blockType)
mc.setBlock(x+3,y,z+2,5)
mc.setBlock(x+3,y,z-1,5)
mc.setBlock(x+3,y,z+3,165)
mc.setBlock(x+3,y,z-2,165)
mc.setBlock(x+4,y,z+3,blockType)
mc.setBlock(x+7,y,z-2,159)
mc.setBlock(x+6,y,z+5,159)
mc.setBlocks(x+4,y+1,z-1,x+5,y,z-1,blockType)
mc.setBlocks(x+6,y+1,z,x+6,y,z+1,blockType)
mc.setBlocks(x+4,y+1,z+2,x+5,y,z+2,blockType)
mc.setBlock(x+3,y+1,z+3,165)
mc.setBlock(x+3,y+1,z-2,165)
mc.setBlock(x+3,y+1,z+2,5)
mc.setBlock(x+3,y+1,z-1,5)
mc.setBlock(x+2,y+1,z+2,blockType)
mc.setBlock(x+2,y+1,z+1,77,4)
mc.setBlock(x+2,y+1,z+3,75,3)

